<?xml version="1.0"?>

<robot name="robot_diff_wheel" xmlns:xacro="http://ros.org/wiki/xacro" >

<xacro:macro name="robot_diff_wheel" params="side_wheel *joint_wheel_pose *mesh_pose">
<!--
########################################################################################
Modelagem da roda "link" "joint" "transmission" "gazebo"
########################################################################################
-->
	<link name="${side_wheel}_wheel">
		<visual>
			<xacro:insert_block name="mesh_pose"/>
			<geometry>
				<mesh filename="package://robot_description/meshes/Wheel.dae" />
			</geometry>
		</visual>
		<collision>
			<xacro:insert_block name="mesh_pose"/>
			<geometry>
				<mesh filename="package://robot_description/meshes/Wheel.dae" />
			</geometry>
		</collision>
		<inertial>
			<xacro:insert_block name="mesh_pose"/>
			<mass value="0.021"/>
			<inertia ixx="4.190e-6" ixy="0.00e+0" ixz="0.00e+0" iyy="4.193e-6" iyz="0.00e+0" izz="7.703e-6"/>
		</inertial>
	</link>

	<joint name="base_to_${side_wheel}_wheel" type="continuous">
		<parent link="chassis"/>
		<child link="${side_wheel}_wheel"/>
		<xacro:insert_block name="joint_wheel_pose"/>
		<axis xyz="0 1 0" rpy="0 0 0" />
	</joint>

	<transmission name="transmission_${side_wheel}_wheel">
		<type>transmission_interface/SimpleTransmission</type>
		<joint name="base_to_${side_wheel}_wheel">
			<hardwareInterface>hardware_interface/VelocityJointInterface</hardwareInterface>
		</joint>
		<actuator name="${side_wheel}_wheel_motor">
			<mechanicalReduction>1</mechanicalReduction>
		</actuator>
	</transmission>

	<gazebo reference="${side_wheel}_wheel">
		<mu1 value="1.0"/>
		<mu2 value="1.0"/>
		<kp value="10000000.0" />
		<kd value="1.0" />
		<fdir1 value="1 0 0"/>
	</gazebo>

</xacro:macro>

</robot>
